#VRML_SIM R2020a utf8
WorldInfo {
  contactProperties [
    ContactProperties {
      material2 "capsule"
      coulombFriction [
        0.2
      ]
    }
    DEF Ball ContactProperties {
      material2 "ball"
      coulombFriction [
        0
      ]
    }
  ]
}
Viewpoint {
  orientation -0.18304790928492537 -0.8610890149410139 -0.4743618568712413 2.4999897151490105
  position -0.836531315019398 1.2518209511537508 -0.5642312646011883
}
Background {
  skyColor [
    0.5 0.2 0.8
  ]
  backUrl [
    "textures/grass.jpg"
  ]
}
DEF NEW_WALL Solid {
  translation -0.5 0.05 0
  children [
    DEF NW Shape {
      appearance Appearance {
        texture ImageTexture {
          url [
            "textures/red_brick_wall.jpg"
          ]
        }
      }
      geometry Box {
        size 0.05 0.3 1
      }
    }
  ]
  name "solid(2)"
  boundingObject USE NW
}
Solid {
  translation -0.01 0.05 0.5
  rotation 0 1 0 -1.5707953071795862
  children [
    USE NW
  ]
  name "solid(3)"
  boundingObject USE NW
}
Solid {
  translation -0.0100002 0.05 -0.51
  rotation 0 1 0 -1.5707953071795862
  children [
    USE NW
  ]
  name "solid(5)"
  boundingObject USE NW
}
Solid {
  translation 0.47 0.05 0
  children [
    USE NW
  ]
  name "solid(4)"
  boundingObject USE NW
}
Solid {
  children [
    DEF FLOOR_GEO Shape {
      appearance Appearance {
        texture ImageTexture {
          url [
            "textures/desktop_wood.jpg"
          ]
        }
      }
      geometry Plane {
      }
    }
  ]
  boundingObject USE FLOOR_GEO
}
Solid {
  translation -0.07 0.35 -0.47
  children [
    DEF BALL_GEO Shape {
      appearance Appearance {
        texture ImageTexture {
          url [
            "textures/varnished_wood.jpg"
          ]
        }
      }
      geometry Sphere {
        radius 0.1
        subdivision 3
      }
    }
  ]
  name "ball"
  contactMaterial "Ball"
  boundingObject USE BALL_GEO
  physics Physics {
    density -1
    mass 5
  }
}
Solid {
  translation -0.43 0.07 0
  rotation 0 0 1 -0.523595307179586
  children [
    DEF BOX_GEO Shape {
      appearance Appearance {
        texture ImageTexture {
          url [
            "textures/steel_floor.jpg"
          ]
        }
      }
      geometry Box {
        size 0.15 0.1 0.2
      }
    }
  ]
  name "Box"
  boundingObject USE BOX_GEO
}
Solid {
  translation -0.41 0.21 -4.06689e-07
  rotation 9.381857096790023e-07 0.7071067811862364 0.7071067811862364 3.14159
  children [
    DEF CAP_GEO Shape {
      appearance Appearance {
        texture ImageTexture {
          url [
            "textures/water.jpg"
          ]
        }
      }
      geometry Capsule {
        height 0.4
        radius 0.05
      }
    }
  ]
  name "solid(1)"
  contactMaterial "capsule"
  boundingObject USE CAP_GEO
  physics Physics {
    density -1
    mass 20
  }
}
Solid {
  translation 0.03 0.2 0.28
  children [
    DEF BALL_GEO Shape {
      appearance Appearance {
        texture ImageTexture {
          url [
            "textures/varnished_wood.jpg"
          ]
        }
      }
      geometry Sphere {
        radius 0.1
        subdivision 3
      }
    }
  ]
  name "ball(1)"
  contactMaterial "Ball"
  boundingObject USE BALL_GEO
  physics Physics {
    density -1
    mass 1
  }
}
Solid {
  translation -0.13 0.55 0.13
  children [
    DEF BALL_GEO Shape {
      appearance Appearance {
        texture ImageTexture {
          url [
            "textures/varnished_wood.jpg"
          ]
        }
      }
      geometry Sphere {
        radius 0.1
        subdivision 3
      }
    }
  ]
  name "ball(2)"
  contactMaterial "Ball"
  boundingObject USE BALL_GEO
  physics Physics {
    density -1
    mass 7
  }
}
Robot {
  translation 0.319912 0.12 -0.324426
  rotation 0 0 1 3.14159
  children [
    DistanceSensor {
      translation 0.0589775 0 -0.0477646
      rotation 0 1 0 0.261799
      name "ds_right"
    }
    DistanceSensor {
      translation 0.0589779 0 0.0477646
      rotation 0 1 0 -0.26179530610042534
      name "ds_left"
    }
    DEF BODY Shape {
      appearance PBRAppearance {
        baseColor 1 0 0
        transparency 0.2
      }
      geometry Capsule {
        height 0.1
        radius 0.05
      }
    }
    DEF W2 HingeJoint {
      jointParameters HingeJointParameters {
        axis 0 0 1
        anchor 0.04 0.08 0.05
      }
      device [
        RotationalMotor {
          name "wheel_2"
        }
      ]
      endPoint Solid {
        translation 0.03999946568787888 0.07999217020980127 0.049999999999955524
        rotation 0.9999982621417528 0.001317588188609686 0.0013189673383086022 1.5707970468542187
        children [
          DEF WHEEL_GEO Shape {
            appearance PBRAppearance {
              baseColor 0 1 1
              roughness 1
              metalness 0
            }
            geometry Cylinder {
              height 0.01
              radius 0.04
            }
          }
        ]
        name "solid(8)"
        boundingObject USE WHEEL_GEO
        physics Physics {
          density -1
          mass 0.25
        }
      }
    }
    DEF W1 HingeJoint {
      jointParameters HingeJointParameters {
        axis 0 0 1
        anchor 0.04 0.08 -0.04
      }
      device [
        RotationalMotor {
          name "wheel_1"
        }
      ]
      endPoint Solid {
        translation 0.04000169725857938 0.07999233692386454 -0.0500000000000444
        rotation 0.9999982633368217 0.0013171265905900268 0.0013185222352828443 1.5707969689325467
        children [
          DEF WHEEL_GEO Shape {
            appearance PBRAppearance {
              baseColor 0 1 1
              roughness 1
              metalness 0
            }
            geometry Cylinder {
              height 0.01
              radius 0.04
            }
          }
        ]
        name "solid(2)"
        boundingObject USE WHEEL_GEO
        physics Physics {
          density -1
          mass 0.25
        }
      }
    }
    DEF W3 HingeJoint {
      jointParameters HingeJointParameters {
        axis 0 0 1
        anchor -0.06 0.08 -0.04
      }
      device [
        RotationalMotor {
          name "wheel_3"
        }
      ]
      endPoint Solid {
        translation -0.0599934 0.0800053 -0.05
        rotation 0.9998313738684814 -0.012985779731278757 -0.012984350312423433 1.5709639833862152
        children [
          DEF WHEEL_GEO Shape {
            appearance PBRAppearance {
              baseColor 0 1 1
              roughness 1
              metalness 0
            }
            geometry Cylinder {
              height 0.01
              radius 0.04
            }
          }
        ]
        name "solid(6)"
        boundingObject USE WHEEL_GEO
        physics Physics {
          density -1
          mass 0.25
        }
      }
    }
    DEF W4 HingeJoint {
      jointParameters HingeJointParameters {
        axis 0 0 1
        anchor -0.06 0.08 0.05
      }
      device [
        RotationalMotor {
          name "wheel_4"
        }
      ]
      endPoint Solid {
        translation -0.059991572430478944 0.07999952017885655 0.049999999987742405
        rotation 0.9996208230620675 -0.019471298889204836 -0.019469941455531867 1.5711745291758445
        children [
          DEF WHEEL_GEO Shape {
            appearance PBRAppearance {
              baseColor 0 1 1
              roughness 1
              metalness 0
            }
            geometry Cylinder {
              height 0.01
              radius 0.04
            }
          }
        ]
        name "solid(1)"
        boundingObject USE WHEEL_GEO
        physics Physics {
          density -1
          mass 0.25
        }
      }
    }
  ]
  name "FourWheelsRobot"
  boundingObject USE BODY
  physics Physics {
    density -1
    mass 2
  }
  controller "3_1Con"
}
